Workbook
Name SegmentaçãodeDados_Ano: #N/A
Name SegmentaçãodeDados_Ano1: #N/A
Name SegmentaçãodeDados_ano2: #N/A
Name SegmentaçãodeDados_Mês: #N/A
Name SegmentaçãodeDados_mes_nome: #N/A
Name SegmentaçãodeDados_Mês1: #N/A
Name SegmentaçãodeDados_tipo_atividade: #N/A
Name SegmentaçãodeDados_Tipo_de_Projeto: #N/A
Name SegmentaçãodeDados_Tipo_de_Projeto1: #N/A

Sheet PROJETOS
A4: ID | B4: Projeto | C4: Descrição | D4: Prioridade | E4: Responsável | F4: FTEs | G4: Valor previsto | H4: Valor gasto | I4: Data Início Planej. | J4: Data Fim Planej. | K4: Data de início | L4: Data Fim Real | M4: Total de tarefas | N4: Tarefas Concluídas | O4: Tarefas em andamento | P4: Tarefas atrasadas | Q4: Tarefas não iniciadas | R4: Status | S4: % de Conclusão
A5: 1 | B5: GAB TUBO SUPERIOR 21, 27 E 35 (980102670500) | C5: Projeto Gabarito Tubo Superior 21,27 e 35 | D5: 3- Alta | E5: Evandro | F5: 1 | G5: 0 | H5: 0 | I5: 45355 | J5: 45381 | K5: =IF(Base_Projetos[[#This Row],[Total de tarefas]]=Base_Projetos[[#This Row],[Tarefas não iniciadas]],"Não iniciado",_xlfn.MINIFS(TAREFAS!H:H,TAREFAS!B:B,Base_Projetos[[#This Row],[Projeto]])) -> 45381 | L5: 45382 | M5: =SUM(Base_Projetos[[#This Row],[Tarefas Concluídas]:[Tarefas não iniciadas]]) -> 3 | N5: =COUNTIFS(tbl_PlanilhaB[Projeto],Base_Projetos[[#This Row],[Projeto]],tbl_PlanilhaB[Status],"Concluído") -> 3 | O5: =COUNTIFS(tbl_PlanilhaB[Projeto],Base_Projetos[[#This Row],[Projeto]],tbl_PlanilhaB[Status],"Em andamento") -> 0 | P5: =COUNTIFS(tbl_PlanilhaB[Projeto],Base_Projetos[[#This Row],[Projeto]],tbl_PlanilhaB[Status],"Atrasado") -> 0 | Q5: =COUNTIFS(tbl_PlanilhaB[Projeto],Base_Projetos[[#This Row],[Projeto]],tbl_PlanilhaB[Status],"Não iniciado") -> 0 | R5: =IF(Base_Projetos[[#This Row],[Total de tarefas]]=Base_Projetos[[#This Row],[Tarefas Concluídas]],"Concluído",IF(Base_Projetos[[#This Row],[Tarefas não iniciadas]]=Base_Projetos[[#This Row],[Total de tarefas]],"Não iniciado",IF(Base_Projetos[[#This Row],[Tarefas atrasadas]]>0,"Atrasado","Em andamento"))) -> Concluído | S5: =Base_Projetos[[#This Row],[Tarefas Concluídas]]/Base_Projetos[[#This Row],[Total de tarefas]] -> 1
A6: =A5+1 -> 2 | B6: GAB ESCADA MAIOR 13, 16, 21, 25T, 32 E 35 (980102640200) | C6: Projeto Gabarito Tubo Superior 13, 16, 21, 25T, 32 E 35 | D6: 3- Alta | E6: Evandro | F6: 1 | G6: =SUMIF(tbl_PlanilhaB[Projeto],Base_Projetos[[#This Row],[Projeto]],tbl_PlanilhaB[Valor previsto]) -> 0 | H6: =SUMIF(tbl_PlanilhaB[Projeto],Base_Projetos[[#This Row],[Projeto]],tbl_PlanilhaB[Valor gasto]) -> 0 | I6: 45355 | J6: 45381 | K6: =IF(Base_Projetos[[#This Row],[Total de tarefas]]=Base_Projetos[[#This Row],[Tarefas não iniciadas]],"Não iniciado",_xlfn.MINIFS(TAREFAS!H:H,TAREFAS!B:B,Base_Projetos[[#This Row],[Projeto]])) -> 45381 | L6: 45382 | M6: =SUM(Base_Projetos[[#This Row],[Tarefas Concluídas]:[Tarefas não iniciadas]]) -> 3 | N6: =COUNTIFS(tbl_PlanilhaB[Projeto],Base_Projetos[[#This Row],[Projeto]],tbl_PlanilhaB[Status],"Concluído") -> 2 | O6: =COUNTIFS(tbl_PlanilhaB[Projeto],Base_Projetos[[#This Row],[Projeto]],tbl_PlanilhaB[Status],"Em andamento") -> 0 | P6: =COUNTIFS(tbl_PlanilhaB[Projeto],Base_Projetos[[#This Row],[Projeto]],tbl_PlanilhaB[Status],"Atrasado") -> 0 | Q6: =COUNTIFS(tbl_PlanilhaB[Projeto],Base_Projetos[[#This Row],[Projeto]],tbl_PlanilhaB[Status],"Não iniciado") -> 1 | R6: =IF(Base_Projetos[[#This Row],[Total de tarefas]]=Base_Projetos[[#This Row],[Tarefas Concluídas]],"Concluído",IF(Base_Projetos[[#This Row],[Tarefas não iniciadas]]=Base_Projetos[[#This Row],[Total de tarefas]],"Não iniciado",IF(Base_Projetos[[#This Row],[Tarefas atrasadas]]>0,"Atrasado","Em andamento"))) -> Em andamento | S6: =Base_Projetos[[#This Row],[Tarefas Concluídas]]/Base_Projetos[[#This Row],[Total de tarefas]] -> 0.66666667
A7: =A6+1 -> 3 | B7: Gabarito Chassi 21000 | C7: Projeto Gabarito Chassi 21000 | D7: 3- Alta | E7: Evandro | F7: 1 | G7: =SUMIF(tbl_PlanilhaB[Projeto],Base_Projetos[[#This Row],[Projeto]],tbl_PlanilhaB[Valor previsto]) -> 0 | H7: =SUMIF(tbl_PlanilhaB[Projeto],Base_Projetos[[#This Row],[Projeto]],tbl_PlanilhaB[Valor gasto]) -> 0 | I7: 45231 | J7: 45245 | K7: =IF(Base_Projetos[[#This Row],[Total de tarefas]]=Base_Projetos[[#This Row],[Tarefas não iniciadas]],"Não iniciado",_xlfn.MINIFS(TAREFAS!H:H,TAREFAS!B:B,Base_Projetos[[#This Row],[Projeto]])) -> 45231 | L7: 45245 | M7: =SUM(Base_Projetos[[#This Row],[Tarefas Concluídas]:[Tarefas não iniciadas]]) -> 3 | N7: =COUNTIFS(tbl_PlanilhaB[Projeto],Base_Projetos[[#This Row],[Projeto]],tbl_PlanilhaB[Status],"Concluído") -> 3 | O7: =COUNTIFS(tbl_PlanilhaB[Projeto],Base_Projetos[[#This Row],[Projeto]],tbl_PlanilhaB[Status],"Em andamento") -> 0 | P7: =COUNTIFS(tbl_PlanilhaB[Projeto],Base_Projetos[[#This Row],[Projeto]],tbl_PlanilhaB[Status],"Atrasado") -> 0 | Q7: =COUNTIFS(tbl_PlanilhaB[Projeto],Base_Projetos[[#This Row],[Projeto]],tbl_PlanilhaB[Status],"Não iniciado") -> 0 | R7: =IF(Base_Projetos[[#This Row],[Total de tarefas]]=Base_Projetos[[#This Row],[Tarefas Concluídas]],"Concluído",IF(Base_Projetos[[#This Row],[Tarefas não iniciadas]]=Base_Projetos[[#This Row],[Total de tarefas]],"Não iniciado",IF(Base_Projetos[[#This Row],[Tarefas atrasadas]]>0,"Atrasado","Em andamento"))) -> Concluído | S7: =Base_Projetos[[#This Row],[Tarefas Concluídas]]/Base_Projetos[[#This Row],[Total de tarefas]] -> 1
A8: =A7+1 -> 4 | B8: Gabarito Caixa Coletora 27000 | C8: Projetar Gabarito Caixa coletora 27000 | D8: 3- Alta | E8: Evandro | F8: 1 | G8: =SUMIF(tbl_PlanilhaB[Projeto],Base_Projetos[[#This Row],[Projeto]],tbl_PlanilhaB[Valor previsto]) -> 0 | H8: =SUMIF(tbl_PlanilhaB[Projeto],Base_Projetos[[#This Row],[Projeto]],tbl_PlanilhaB[Valor gasto]) -> 0 | I8: =_xlfn.MINIFS(TAREFAS!E:E,TAREFAS!B:B,Base_Projetos[[#This Row],[Projeto]]) -> 45232 | J8: =_xlfn.MAXIFS(TAREFAS!G:G,TAREFAS!B:B,Base_Projetos[[#This Row],[Projeto]]) -> 45246 | K8: =IF(Base_Projetos[[#This Row],[Total de tarefas]]=Base_Projetos[[#This Row],[Tarefas não iniciadas]],"Não iniciado",_xlfn.MINIFS(TAREFAS!H:H,TAREFAS!B:B,Base_Projetos[[#This Row],[Projeto]])) -> 45232 | L8: =IF(Base_Projetos[[#This Row],[Total de tarefas]]=Base_Projetos[[#This Row],[Tarefas Concluídas]],_xlfn.MAXIFS(TAREFAS!H:H,TAREFAS!B:B,Base_Projetos[[#This Row],[Projeto]]),IF(Base_Projetos[[#This Row],[Total de tarefas]]=Base_Projetos[[#This Row],[Tarefas não iniciadas]],"Não iniciado","Em andamento")) -> 45232 | M8: =SUM(Base_Projetos[[#This Row],[Tarefas Concluídas]:[Tarefas não iniciadas]]) -> 1 | N8: =COUNTIFS(tbl_PlanilhaB[Projeto],Base_Projetos[[#This Row],[Projeto]],tbl_PlanilhaB[Status],"Concluído") -> 1 | O8: =COUNTIFS(tbl_PlanilhaB[Projeto],Base_Projetos[[#This Row],[Projeto]],tbl_PlanilhaB[Status],"Em andamento") -> 0 | P8: =COUNTIFS(tbl_PlanilhaB[Projeto],Base_Projetos[[#This Row],[Projeto]],tbl_PlanilhaB[Status],"Atrasado") -> 0 | Q8: =COUNTIFS(tbl_PlanilhaB[Projeto],Base_Projetos[[#This Row],[Projeto]],tbl_PlanilhaB[Status],"Não iniciado") -> 0 | R8: =IF(Base_Projetos[[#This Row],[Total de tarefas]]=Base_Projetos[[#This Row],[Tarefas Concluídas]],"Concluído",IF(Base_Projetos[[#This Row],[Tarefas não iniciadas]]=Base_Projetos[[#This Row],[Total de tarefas]],"Não iniciado",IF(Base_Projetos[[#This Row],[Tarefas atrasadas]]>0,"Atrasado","Em andamento"))) -> Concluído | S8: =Base_Projetos[[#This Row],[Tarefas Concluídas]]/Base_Projetos[[#This Row],[Total de tarefas]] -> 1
A9: =A8+1 -> 5 | B9: Gabarito Chassi 27000 | C9: Projetar Gabarito Chassi 27000 | D9: 3- Alta | E9: Evandro | F9: 1 | G9: =SUMIF(tbl_PlanilhaB[Projeto],Base_Projetos[[#This Row],[Projeto]],tbl_PlanilhaB[Valor previsto]) -> 0 | H9: =SUMIF(tbl_PlanilhaB[Projeto],Base_Projetos[[#This Row],[Projeto]],tbl_PlanilhaB[Valor gasto]) -> 0 | I9: =_xlfn.MINIFS(TAREFAS!E:E,TAREFAS!B:B,Base_Projetos[[#This Row],[Projeto]]) -> 45243 | J9: =_xlfn.MAXIFS(TAREFAS!G:G,TAREFAS!B:B,Base_Projetos[[#This Row],[Projeto]]) -> 45257 | K9: =IF(Base_Projetos[[#This Row],[Total de tarefas]]=Base_Projetos[[#This Row],[Tarefas não iniciadas]],"Não iniciado",_xlfn.MINIFS(TAREFAS!H:H,TAREFAS!B:B,Base_Projetos[[#This Row],[Projeto]])) -> 45243 | L9: =IF(Base_Projetos[[#This Row],[Total de tarefas]]=Base_Projetos[[#This Row],[Tarefas Concluídas]],_xlfn.MAXIFS(TAREFAS!H:H,TAREFAS!B:B,Base_Projetos[[#This Row],[Projeto]]),IF(Base_Projetos[[#This Row],[Total de tarefas]]=Base_Projetos[[#This Row],[Tarefas não iniciadas]],"Não iniciado","Em andamento")) -> 45243 | M9: =SUM(Base_Projetos[[#This Row],[Tarefas Concluídas]:[Tarefas não iniciadas]]) -> 1 | N9: =COUNTIFS(tbl_PlanilhaB[Projeto],Base_Projetos[[#This Row],[Projeto]],tbl_PlanilhaB[Status],"Concluído") -> 1 | O9: =COUNTIFS(tbl_PlanilhaB[Projeto],Base_Projetos[[#This Row],[Projeto]],tbl_PlanilhaB[Status],"Em andamento") -> 0 | P9: =COUNTIFS(tbl_PlanilhaB[Projeto],Base_Projetos[[#This Row],[Projeto]],tbl_PlanilhaB[Status],"Atrasado") -> 0 | Q9: =COUNTIFS(tbl_PlanilhaB[Projeto],Base_Projetos[[#This Row],[Projeto]],tbl_PlanilhaB[Status],"Não iniciado") -> 0 | R9: =IF(Base_Projetos[[#This Row],[Total de tarefas]]=Base_Projetos[[#This Row],[Tarefas Concluídas]],"Concluído",IF(Base_Projetos[[#This Row],[Tarefas não iniciadas]]=Base_Projetos[[#This Row],[Total de tarefas]],"Não iniciado",IF(Base_Projetos[[#This Row],[Tarefas atrasadas]]>0,"Atrasado","Em andamento"))) -> Concluído | S9: =Base_Projetos[[#This Row],[Tarefas Concluídas]]/Base_Projetos[[#This Row],[Total de tarefas]] -> 1
A10: =A9+1 -> 6 | B10: Gabarito Reforço Frontal 27000 | C10: Projetar Gabarito Reforço Frontal 27000 | D10: 3- Alta | E10: Fabricio | F10: 1 | G10: =SUMIF(tbl_PlanilhaB[Projeto],Base_Projetos[[#This Row],[Projeto]],tbl_PlanilhaB[Valor previsto]) -> 0 | H10: =SUMIF(tbl_PlanilhaB[Projeto],Base_Projetos[[#This Row],[Projeto]],tbl_PlanilhaB[Valor gasto]) -> 0 | I10: =_xlfn.MINIFS(TAREFAS!E:E,TAREFAS!B:B,Base_Projetos[[#This Row],[Projeto]]) -> 45237 | J10: =_xlfn.MAXIFS(TAREFAS!G:G,TAREFAS!B:B,Base_Projetos[[#This Row],[Projeto]]) -> 45258 | K10: =IF(Base_Projetos[[#This Row],[Total de tarefas]]=Base_Projetos[[#This Row],[Tarefas não iniciadas]],"Não iniciado",_xlfn.MINIFS(TAREFAS!H:H,TAREFAS!B:B,Base_Projetos[[#This Row],[Projeto]])) -> 45237 | L10: =IF(Base_Projetos[[#This Row],[Total de tarefas]]=Base_Projetos[[#This Row],[Tarefas Concluídas]],_xlfn.MAXIFS(TAREFAS!H:H,TAREFAS!B:B,Base_Projetos[[#This Row],[Projeto]]),IF(Base_Projetos[[#This Row],[Total de tarefas]]=Base_Projetos[[#This Row],[Tarefas não iniciadas]],"Não iniciado","Em andamento")) -> 45237 | M10: =SUM(Base_Projetos[[#This Row],[Tarefas Concluídas]:[Tarefas não iniciadas]]) -> 1 | N10: =COUNTIFS(tbl_PlanilhaB[Projeto],Base_Projetos[[#This Row],[Projeto]],tbl_PlanilhaB[Status],"Concluído") -> 1 | O10: =COUNTIFS(tbl_PlanilhaB[Projeto],Base_Projetos[[#This Row],[Projeto]],tbl_PlanilhaB[Status],"Em andamento") -> 0 | P10: =COUNTIFS(tbl_PlanilhaB[Projeto],Base_Projetos[[#This Row],[Projeto]],tbl_PlanilhaB[Status],"Atrasado") -> 0 | Q10: =COUNTIFS(tbl_PlanilhaB[Projeto],Base_Projetos[[#This Row],[Projeto]],tbl_PlanilhaB[Status],"Não iniciado") -> 0 | R10: =IF(Base_Projetos[[#This Row],[Total de tarefas]]=Base_Projetos[[#This Row],[Tarefas Concluídas]],"Concluído",IF(Base_Projetos[[#This Row],[Tarefas não iniciadas]]=Base_Projetos[[#This Row],[Total de tarefas]],"Não iniciado",IF(Base_Projetos[[#This Row],[Tarefas atrasadas]]>0,"Atrasado","Em andamento"))) -> Concluído | S10: =Base_Projetos[[#This Row],[Tarefas Concluídas]]/Base_Projetos[[#This Row],[Total de tarefas]] -> 1
A11: =A10+1 -> 7 | B11: Gabarito Reforço traseiro 27000 | C11: Projetar Gabarito Reforço Traseiro 27000 | D11: 3- Alta | E11: Fabricio | F11: 1 | G11: =SUMIF(tbl_PlanilhaB[Projeto],Base_Projetos[[#This Row],[Projeto]],tbl_PlanilhaB[Valor previsto]) -> 0 | H11: =SUMIF(tbl_PlanilhaB[Projeto],Base_Projetos[[#This Row],[Projeto]],tbl_PlanilhaB[Valor gasto]) -> 0 | I11: =_xlfn.MINIFS(TAREFAS!E:E,TAREFAS!B:B,Base_Projetos[[#This Row],[Projeto]]) -> 45247 | J11: =_xlfn.MAXIFS(TAREFAS!G:G,TAREFAS!B:B,Base_Projetos[[#This Row],[Projeto]]) -> 45268 | K11: =IF(Base_Projetos[[#This Row],[Total de tarefas]]=Base_Projetos[[#This Row],[Tarefas não iniciadas]],"Não iniciado",_xlfn.MINIFS(TAREFAS!H:H,TAREFAS!B:B,Base_Projetos[[#This Row],[Projeto]])) -> 45247 | L11: =IF(Base_Projetos[[#This Row],[Total de tarefas]]=Base_Projetos[[#This Row],[Tarefas Concluídas]],_xlfn.MAXIFS(TAREFAS!H:H,TAREFAS!B:B,Base_Projetos[[#This Row],[Projeto]]),IF(Base_Projetos[[#This Row],[Total de tarefas]]=Base_Projetos[[#This Row],[Tarefas não iniciadas]],"Não iniciado","Em andamento")) -> 45247 | M11: =SUM(Base_Projetos[[#This Row],[Tarefas Concluídas]:[Tarefas não iniciadas]]) -> 1 | N11: =COUNTIFS(tbl_PlanilhaB[Projeto],Base_Projetos[[#This Row],[Projeto]],tbl_PlanilhaB[Status],"Concluído") -> 1 | O11: =COUNTIFS(tbl_PlanilhaB[Projeto],Base_Projetos[[#This Row],[Projeto]],tbl_PlanilhaB[Status],"Em andamento") -> 0 | P11: =COUNTIFS(tbl_PlanilhaB[Projeto],Base_Projetos[[#This Row],[Projeto]],tbl_PlanilhaB[Status],"Atrasado") -> 0 | Q11: =COUNTIFS(tbl_PlanilhaB[Projeto],Base_Projetos[[#This Row],[Projeto]],tbl_PlanilhaB[Status],"Não iniciado") -> 0 | R11: =IF(Base_Projetos[[#This Row],[Total de tarefas]]=Base_Projetos[[#This Row],[Tarefas Concluídas]],"Concluído",IF(Base_Projetos[[#This Row],[Tarefas não iniciadas]]=Base_Projetos[[#This Row],[Total de tarefas]],"Não iniciado",IF(Base_Projetos[[#This Row],[Tarefas atrasadas]]>0,"Atrasado","Em andamento"))) -> Concluído | S11: =Base_Projetos[[#This Row],[Tarefas Concluídas]]/Base_Projetos[[#This Row],[Total de tarefas]] -> 1
A12: =A11+1 -> 8 | B12: Gabarito Reforço Lateral 27000 | C12: Projetar Gabarito Reforço Lateral 27000 | D12: 3- Alta | E12: Fabricio | F12: 1 | G12: =SUMIF(tbl_PlanilhaB[Projeto],Base_Projetos[[#This Row],[Projeto]],tbl_PlanilhaB[Valor previsto]) -> 0 | H12: =SUMIF(tbl_PlanilhaB[Projeto],Base_Projetos[[#This Row],[Projeto]],tbl_PlanilhaB[Valor gasto]) -> 0 | I12: =_xlfn.MINIFS(TAREFAS!E:E,TAREFAS!B:B,Base_Projetos[[#This Row],[Projeto]]) -> 45254 | J12: =_xlfn.MAXIFS(TAREFAS!G:G,TAREFAS!B:B,Base_Projetos[[#This Row],[Projeto]]) -> 45268 | K12: =IF(Base_Projetos[[#This Row],[Total de tarefas]]=Base_Projetos[[#This Row],[Tarefas não iniciadas]],"Não iniciado",_xlfn.MINIFS(TAREFAS!H:H,TAREFAS!B:B,Base_Projetos[[#This Row],[Projeto]])) -> 45254 | L12: =IF(Base_Projetos[[#This Row],[Total de tarefas]]=Base_Projetos[[#This Row],[Tarefas Concluídas]],_xlfn.MAXIFS(TAREFAS!H:H,TAREFAS!B:B,Base_Projetos[[#This Row],[Projeto]]),IF(Base_Projetos[[#This Row],[Total de tarefas]]=Base_Projetos[[#This Row],[Tarefas não iniciadas]],"Não iniciado","Em andamento")) -> 45254 | M12: =SUM(Base_Projetos[[#This Row],[Tarefas Concluídas]:[Tarefas não iniciadas]]) -> 1 | N12: =COUNTIFS(tbl_PlanilhaB[Projeto],Base_Projetos[[#This Row],[Projeto]],tbl_PlanilhaB[Status],"Concluído") -> 1 | O12: =COUNTIFS(tbl_PlanilhaB[Projeto],Base_Projetos[[#This Row],[Projeto]],tbl_PlanilhaB[Status],"Em andamento") -> 0 | P12: =COUNTIFS(tbl_PlanilhaB[Projeto],Base_Projetos[[#This Row],[Projeto]],tbl_PlanilhaB[Status],"Atrasado") -> 0 | Q12: =COUNTIFS(tbl_PlanilhaB[Projeto],Base_Projetos[[#This Row],[Projeto]],tbl_PlanilhaB[Status],"Não iniciado") -> 0 | R12: =IF(Base_Projetos[[#This Row],[Total de tarefas]]=Base_Projetos[[#This Row],[Tarefas Concluídas]],"Concluído",IF(Base_Projetos[[#This Row],[Tarefas não iniciadas]]=Base_Projetos[[#This Row],[Total de tarefas]],"Não iniciado",IF(Base_Projetos[[#This Row],[Tarefas atrasadas]]>0,"Atrasado","Em andamento"))) -> Concluído | S12: =Base_Projetos[[#This Row],[Tarefas Concluídas]]/Base_Projetos[[#This Row],[Total de tarefas]] -> 1
A13: =A12+1 -> 9 | B13: Gabarito Caixa Coletora 21000 | C13: Projetar Gabarito Caixa Coletora 21000 | D13: 3- Alta | E13: Evandro | F13: 1 | G13: =SUMIF(tbl_PlanilhaB[Projeto],Base_Projetos[[#This Row],[Projeto]],tbl_PlanilhaB[Valor previsto]) -> 0 | H13: =SUMIF(tbl_PlanilhaB[Projeto],Base_Projetos[[#This Row],[Projeto]],tbl_PlanilhaB[Valor gasto]) -> 0 | I13: =_xlfn.MINIFS(TAREFAS!E:E,TAREFAS!B:B,Base_Projetos[[#This Row],[Projeto]]) -> 45020 | J13: =_xlfn.MAXIFS(TAREFAS!G:G,TAREFAS!B:B,Base_Projetos[[#This Row],[Projeto]]) -> 45275 | K13: =IF(Base_Projetos[[#This Row],[Total de tarefas]]=Base_Projetos[[#This Row],[Tarefas não iniciadas]],"Não iniciado",_xlfn.MINIFS(TAREFAS!H:H,TAREFAS!B:B,Base_Projetos[[#This Row],[Projeto]])) -> 45020 | L13: =IF(Base_Projetos[[#This Row],[Total de tarefas]]=Base_Projetos[[#This Row],[Tarefas Concluídas]],_xlfn.MAXIFS(TAREFAS!H:H,TAREFAS!B:B,Base_Projetos[[#This Row],[Projeto]]),IF(Base_Projetos[[#This Row],[Total de tarefas]]=Base_Projetos[[#This Row],[Tarefas não iniciadas]],"Não iniciado","Em andamento")) -> 45261 | M13: =SUM(Base_Projetos[[#This Row],[Tarefas Concluídas]:[Tarefas não iniciadas]]) -> 2 | N13: =COUNTIFS(tbl_PlanilhaB[Projeto],Base_Projetos[[#This Row],[Projeto]],tbl_PlanilhaB[Status],"Concluído") -> 2 | O13: =COUNTIFS(tbl_PlanilhaB[Projeto],Base_Projetos[[#This Row],[Projeto]],tbl_PlanilhaB[Status],"Em andamento") -> 0 | P13: =COUNTIFS(tbl_PlanilhaB[Projeto],Base_Projetos[[#This Row],[Projeto]],tbl_PlanilhaB[Status],"Atrasado") -> 0 | Q13: =COUNTIFS(tbl_PlanilhaB[Projeto],Base_Projetos[[#This Row],[Projeto]],tbl_PlanilhaB[Status],"Não iniciado") -> 0 | R13: =IF(Base_Projetos[[#This Row],[Total de tarefas]]=Base_Projetos[[#This Row],[Tarefas Concluídas]],"Concluído",IF(Base_Projetos[[#This Row],[Tarefas não iniciadas]]=Base_Projetos[[#This Row],[Total de tarefas]],"Não iniciado",IF(Base_Projetos[[#This Row],[Tarefas atrasadas]]>0,"Atrasado","Em andamento"))) -> Concluído | S13: =Base_Projetos[[#This Row],[Tarefas Concluídas]]/Base_Projetos[[#This Row],[Total de tarefas]] -> 1
A14: =A13+1 -> 10 | B14: Gabarito Funil 27000 | C14: Projetar Gabarito Funil 27000 | D14: 3- Alta | E14: Fabricio | F14: 1 | G14: =SUMIF(tbl_PlanilhaB[Projeto],Base_Projetos[[#This Row],[Projeto]],tbl_PlanilhaB[Valor previsto]) -> 0 | H14: =SUMIF(tbl_PlanilhaB[Projeto],Base_Projetos[[#This Row],[Projeto]],tbl_PlanilhaB[Valor gasto]) -> 0 | I14: =_xlfn.MINIFS(TAREFAS!E:E,TAREFAS!B:B,Base_Projetos[[#This Row],[Projeto]]) -> 45264 | J14: =_xlfn.MAXIFS(TAREFAS!G:G,TAREFAS!B:B,Base_Projetos[[#This Row],[Projeto]]) -> 45285 | K14: =IF(Base_Projetos[[#This Row],[Total de tarefas]]=Base_Projetos[[#This Row],[Tarefas não iniciadas]],"Não iniciado",_xlfn.MINIFS(TAREFAS!H:H,TAREFAS!B:B,Base_Projetos[[#This Row],[Projeto]])) -> 45264 | L14: =IF(Base_Projetos[[#This Row],[Total de tarefas]]=Base_Projetos[[#This Row],[Tarefas Concluídas]],_xlfn.MAXIFS(TAREFAS!H:H,TAREFAS!B:B,Base_Projetos[[#This Row],[Projeto]]),IF(Base_Projetos[[#This Row],[Total de tarefas]]=Base_Projetos[[#This Row],[Tarefas não iniciadas]],"Não iniciado","Em andamento")) -> 45264 | M14: =SUM(Base_Projetos[[#This Row],[Tarefas Concluídas]:[Tarefas não iniciadas]]) -> 1 | N14: =COUNTIFS(tbl_PlanilhaB[Projeto],Base_Projetos[[#This Row],[Projeto]],tbl_PlanilhaB[Status],"Concluído") -> 1 | O14: =COUNTIFS(tbl_PlanilhaB[Projeto],Base_Projetos[[#This Row],[Projeto]],tbl_PlanilhaB[Status],"Em andamento") -> 0 | P14: =COUNTIFS(tbl_PlanilhaB[Projeto],Base_Projetos[[#This Row],[Projeto]],tbl_PlanilhaB[Status],"Atrasado") -> 0 | Q14: =COUNTIFS(tbl_PlanilhaB[Projeto],Base_Projetos[[#This Row],[Projeto]],tbl_PlanilhaB[Status],"Não iniciado") -> 0 | R14: =IF(Base_Projetos[[#This Row],[Total de tarefas]]=Base_Projetos[[#This Row],[Tarefas Concluídas]],"Concluído",IF(Base_Projetos[[#This Row],[Tarefas não iniciadas]]=Base_Projetos[[#This Row],[Total de tarefas]],"Não iniciado",IF(Base_Projetos[[#This Row],[Tarefas atrasadas]]>0,"Atrasado","Em andamento"))) -> Concluído | S14: =Base_Projetos[[#This Row],[Tarefas Concluídas]]/Base_Projetos[[#This Row],[Total de tarefas]] -> 1
A15: =A14+1 -> 11 | B15: Gabarito Chassi Rob 440/480 | C15: Projetar Gabarito Chassi Rob 440/480 | D15: 3- Alta | E15: Fabricio | F15: 1 | G15: =SUMIF(tbl_PlanilhaB[Projeto],Base_Projetos[[#This Row],[Projeto]],tbl_PlanilhaB[Valor previsto]) -> 0 | H15: =SUMIF(tbl_PlanilhaB[Projeto],Base_Projetos[[#This Row],[Projeto]],tbl_PlanilhaB[Valor gasto]) -> 0 | I15: =_xlfn.MINIFS(TAREFAS!E:E,TAREFAS!B:B,Base_Projetos[[#This Row],[Projeto]]) -> 45267 | J15: =_xlfn.MAXIFS(TAREFAS!G:G,TAREFAS!B:B,Base_Projetos[[#This Row],[Projeto]]) -> 45407 | K15: =IF(Base_Projetos[[#This Row],[Total de tarefas]]=Base_Projetos[[#This Row],[Tarefas não iniciadas]],"Não iniciado",_xlfn.MINIFS(TAREFAS!H:H,TAREFAS!B:B,Base_Projetos[[#This Row],[Projeto]])) -> 45267 | L15: =IF(Base_Projetos[[#This Row],[Total de tarefas]]=Base_Projetos[[#This Row],[Tarefas Concluídas]],_xlfn.MAXIFS(TAREFAS!H:H,TAREFAS!B:B,Base_Projetos[[#This Row],[Projeto]]),IF(Base_Projetos[[#This Row],[Total de tarefas]]=Base_Projetos[[#This Row],[Tarefas não iniciadas]],"Não iniciado","Em andamento")) -> 45406 | M15: =SUM(Base_Projetos[[#This Row],[Tarefas Concluídas]:[Tarefas não iniciadas]]) -> 2 | N15: =COUNTIFS(tbl_PlanilhaB[Projeto],Base_Projetos[[#This Row],[Projeto]],tbl_PlanilhaB[Status],"Concluído") -> 2 | O15: =COUNTIFS(tbl_PlanilhaB[Projeto],Base_Projetos[[#This Row],[Projeto]],tbl_PlanilhaB[Status],"Em andamento") -> 0 | P15: =COUNTIFS(tbl_PlanilhaB[Projeto],Base_Projetos[[#This Row],[Projeto]],tbl_PlanilhaB[Status],"Atrasado") -> 0 | Q15: =COUNTIFS(tbl_PlanilhaB[Projeto],Base_Projetos[[#This Row],[Projeto]],tbl_PlanilhaB[Status],"Não iniciado") -> 0 | R15: =IF(Base_Projetos[[#This Row],[Total de tarefas]]=Base_Projetos[[#This Row],[Tarefas Concluídas]],"Concluído",IF(Base_Projetos[[#This Row],[Tarefas não iniciadas]]=Base_Projetos[[#This Row],[Total de tarefas]],"Não iniciado",IF(Base_Projetos[[#This Row],[Tarefas atrasadas]]>0,"Atrasado","Em andamento"))) -> Concluído | S15: =Base_Projetos[[#This Row],[Tarefas Concluídas]]/Base_Projetos[[#This Row],[Total de tarefas]] -> 1
A16: =A15+1 -> 12 | B16: Gabarito Tubo Intermediário 21, 25T e 27 Complemento | C16: Projetar Gabarito Tubo Intermediário 21,25T e 27 Complemento | D16: 3- Alta | E16: Evandro | F16: 1 | G16: =SUMIF(tbl_PlanilhaB[Projeto],Base_Projetos[[#This Row],[Projeto]],tbl_PlanilhaB[Valor previsto]) -> 0 | H16: =SUMIF(tbl_PlanilhaB[Projeto],Base_Projetos[[#This Row],[Projeto]],tbl_PlanilhaB[Valor gasto]) -> 0 | I16: =_xlfn.MINIFS(TAREFAS!E:E,TAREFAS!B:B,Base_Projetos[[#This Row],[Projeto]]) -> 45267 | J16: =_xlfn.MAXIFS(TAREFAS!G:G,TAREFAS!B:B,Base_Projetos[[#This Row],[Projeto]]) -> 45281 | K16: =IF(Base_Projetos[[#This Row],[Total de tarefas]]=Base_Projetos[[#This Row],[Tarefas não iniciadas]],"Não iniciado",_xlfn.MINIFS(TAREFAS!H:H,TAREFAS!B:B,Base_Projetos[[#This Row],[Projeto]])) -> 45267 | L16: =IF(Base_Projetos[[#This Row],[Total de tarefas]]=Base_Projetos[[#This Row],[Tarefas Concluídas]],_xlfn.MAXIFS(TAREFAS!H:H,TAREFAS!B:B,Base_Projetos[[#This Row],[Projeto]]),IF(Base_Projetos[[#This Row],[Total de tarefas]]=Base_Projetos[[#This Row],[Tarefas não iniciadas]],"Não iniciado","Em andamento")) -> Em andamento | M16: =SUM(Base_Projetos[[#This Row],[Tarefas Concluídas]:[Tarefas não iniciadas]]) -> 2 | N16: =COUNTIFS(tbl_PlanilhaB[Projeto],Base_Projetos[[#This Row],[Projeto]],tbl_PlanilhaB[Status],"Concluído") -> 1 | O16: =COUNTIFS(tbl_PlanilhaB[Projeto],Base_Projetos[[#This Row],[Projeto]],tbl_PlanilhaB[Status],"Em andamento") -> 0 | P16: =COUNTIFS(tbl_PlanilhaB[Projeto],Base_Projetos[[#This Row],[Projeto]],tbl_PlanilhaB[Status],"Atrasado") -> 0 | Q16: =COUNTIFS(tbl_PlanilhaB[Projeto],Base_Projetos[[#This Row],[Projeto]],tbl_PlanilhaB[Status],"Não iniciado") -> 1 | R16: =IF(Base_Projetos[[#This Row],[Total de tarefas]]=Base_Projetos[[#This Row],[Tarefas Concluídas]],"Concluído",IF(Base_Projetos[[#This Row],[Tarefas não iniciadas]]=Base_Projetos[[#This Row],[Total de tarefas]],"Não iniciado",IF(Base_Projetos[[#This Row],[Tarefas atrasadas]]>0,"Atrasado","Em andamento"))) -> Em andamento | S16: =Base_Projetos[[#This Row],[Tarefas Concluídas]]/Base_Projetos[[#This Row],[Total de tarefas]] -> 0.5
A17: =A16+1 -> 13 | B17: Gabarito Tubo Intermediário 27 | C17: Projetar Gabarito Tubo Intermediário 27000 | D17: 3- Alta | E17: Evandro | F17: 1 | G17: =SUMIF(tbl_PlanilhaB[Projeto],Base_Projetos[[#This Row],[Projeto]],tbl_PlanilhaB[Valor previsto]) -> 0 | H17: =SUMIF(tbl_PlanilhaB[Projeto],Base_Projetos[[#This Row],[Projeto]],tbl_PlanilhaB[Valor gasto]) -> 0 | I17: =_xlfn.MINIFS(TAREFAS!E:E,TAREFAS!B:B,Base_Projetos[[#This Row],[Projeto]]) -> 45281 | J17: =_xlfn.MAXIFS(TAREFAS!G:G,TAREFAS!B:B,Base_Projetos[[#This Row],[Projeto]]) -> 45295 | K17: =IF(Base_Projetos[[#This Row],[Total de tarefas]]=Base_Projetos[[#This Row],[Tarefas não iniciadas]],"Não iniciado",_xlfn.MINIFS(TAREFAS!H:H,TAREFAS!B:B,Base_Projetos[[#This Row],[Projeto]])) -> 45281 | L17: =IF(Base_Projetos[[#This Row],[Total de tarefas]]=Base_Projetos[[#This Row],[Tarefas Concluídas]],_xlfn.MAXIFS(TAREFAS!H:H,TAREFAS!B:B,Base_Projetos[[#This Row],[Projeto]]),IF(Base_Projetos[[#This Row],[Total de tarefas]]=Base_Projetos[[#This Row],[Tarefas não iniciadas]],"Não iniciado","Em andamento")) -> 45281 | M17: =SUM(Base_Projetos[[#This Row],[Tarefas Concluídas]:[Tarefas não iniciadas]]) -> 1 | N17: =COUNTIFS(tbl_PlanilhaB[Projeto],Base_Projetos[[#This Row],[Projeto]],tbl_PlanilhaB[Status],"Concluído") -> 1 | O17: =COUNTIFS(tbl_PlanilhaB[Projeto],Base_Projetos[[#This Row],[Projeto]],tbl_PlanilhaB[Status],"Em andamento") -> 0 | P17: =COUNTIFS(tbl_PlanilhaB[Projeto],Base_Projetos[[#This Row],[Projeto]],tbl_PlanilhaB[Status],"Atrasado") -> 0 | Q17: =COUNTIFS(tbl_PlanilhaB[Projeto],Base_Projetos[[#This Row],[Projeto]],tbl_PlanilhaB[Status],"Não iniciado") -> 0 | R17: =IF(Base_Projetos[[#This Row],[Total de tarefas]]=Base_Projetos[[#This Row],[Tarefas Concluídas]],"Concluído",IF(Base_Projetos[[#This Row],[Tarefas não iniciadas]]=Base_Projetos[[#This Row],[Total de tarefas]],"Não iniciado",IF(Base_Projetos[[#This Row],[Tarefas atrasadas]]>0,"Atrasado","Em andamento"))) -> Concluído | S17: =Base_Projetos[[#This Row],[Tarefas Concluídas]]/Base_Projetos[[#This Row],[Total de tarefas]] -> 1
A18: =A17+1 -> 14 | B18: Gabarito Cintas Soldadas 21, 25 e 27 | C18: Projetar Gabarito Cintas Soldadas 21,25 e 27 | D18: 3- Alta | E18: Evandro | F18: 1 | G18: =SUMIF(tbl_PlanilhaB[Projeto],Base_Projetos[[#This Row],[Projeto]],tbl_PlanilhaB[Valor previsto]) -> 0 | H18: =SUMIF(tbl_PlanilhaB[Projeto],Base_Projetos[[#This Row],[Projeto]],tbl_PlanilhaB[Valor gasto]) -> 0 | I18: =_xlfn.MINIFS(TAREFAS!E:E,TAREFAS!B:B,Base_Projetos[[#This Row],[Projeto]]) -> 45287 | J18: =_xlfn.MAXIFS(TAREFAS!G:G,TAREFAS!B:B,Base_Projetos[[#This Row],[Projeto]]) -> 45296 | K18: =IF(Base_Projetos[[#This Row],[Total de tarefas]]=Base_Projetos[[#This Row],[Tarefas não iniciadas]],"Não iniciado",_xlfn.MINIFS(TAREFAS!H:H,TAREFAS!B:B,Base_Projetos[[#This Row],[Projeto]])) -> 45287 | L18: =IF(Base_Projetos[[#This Row],[Total de tarefas]]=Base_Projetos[[#This Row],[Tarefas Concluídas]],_xlfn.MAXIFS(TAREFAS!H:H,TAREFAS!B:B,Base_Projetos[[#This Row],[Projeto]]),IF(Base_Projetos[[#This Row],[Total de tarefas]]=Base_Projetos[[#This Row],[Tarefas não iniciadas]],"Não iniciado","Em andamento")) -> 45287 | M18: =SUM(Base_Projetos[[#This Row],[Tarefas Concluídas]:[Tarefas não iniciadas]]) -> 1 | N18: =COUNTIFS(tbl_PlanilhaB[Projeto],Base_Projetos[[#This Row],[Projeto]],tbl_PlanilhaB[Status],"Concluído") -> 1 | O18: =COUNTIFS(tbl_PlanilhaB[Projeto],Base_Projetos[[#This Row],[Projeto]],tbl_PlanilhaB[Status],"Em andamento") -> 0 | P18: =COUNTIFS(tbl_PlanilhaB[Projeto],Base_Projetos[[#This Row],[Projeto]],tbl_PlanilhaB[Status],"Atrasado") -> 0 | Q18: =COUNTIFS(tbl_PlanilhaB[Projeto],Base_Projetos[[#This Row],[Projeto]],tbl_PlanilhaB[Status],"Não iniciado") -> 0 | R18: =IF(Base_Projetos[[#This Row],[Total de tarefas]]=Base_Projetos[[#This Row],[Tarefas Concluídas]],"Concluído",IF(Base_Projetos[[#This Row],[Tarefas não iniciadas]]=Base_Projetos[[#This Row],[Total de tarefas]],"Não iniciado",IF(Base_Projetos[[#This Row],[Tarefas atrasadas]]>0,"Atrasado","Em andamento"))) -> Concluído | S18: =Base_Projetos[[#This Row],[Tarefas Concluídas]]/Base_Projetos[[#This Row],[Total de tarefas]] -> 1
A19: =A18+1 -> 15 | B19: Gabarito Caixa Coletora 16000 | C19: Projetar Gabarito Caixa Coletora 16000 | D19: 3- Alta | E19: Evandro | F19: 1 | G19: =SUMIF(tbl_PlanilhaB[Projeto],Base_Projetos[[#This Row],[Projeto]],tbl_PlanilhaB[Valor previsto]) -> 0 | H19: =SUMIF(tbl_PlanilhaB[Projeto],Base_Projetos[[#This Row],[Projeto]],tbl_PlanilhaB[Valor gasto]) -> 0 | I19: =_xlfn.MINIFS(TAREFAS!E:E,TAREFAS!B:B,Base_Projetos[[#This Row],[Projeto]]) -> 45296 | J19: =_xlfn.MAXIFS(TAREFAS!G:G,TAREFAS!B:B,Base_Projetos[[#This Row],[Projeto]]) -> 45399 | K19: =IF(Base_Projetos[[#This Row],[Total de tarefas]]=Base_Projetos[[#This Row],[Tarefas não iniciadas]],"Não iniciado",_xlfn.MINIFS(TAREFAS!H:H,TAREFAS!B:B,Base_Projetos[[#This Row],[Projeto]])) -> 45296 | L19: =IF(Base_Projetos[[#This Row],[Total de tarefas]]=Base_Projetos[[#This Row],[Tarefas Concluídas]],_xlfn.MAXIFS(TAREFAS!H:H,TAREFAS!B:B,Base_Projetos[[#This Row],[Projeto]]),IF(Base_Projetos[[#This Row],[Total de tarefas]]=Base_Projetos[[#This Row],[Tarefas não iniciadas]],"Não iniciado","Em andamento")) -> 45397 | M19: =SUM(Base_Projetos[[#This Row],[Tarefas Concluídas]:[Tarefas não iniciadas]]) -> 2 | N19: =COUNTIFS(tbl_PlanilhaB[Projeto],Base_Projetos[[#This Row],[Projeto]],tbl_PlanilhaB[Status],"Concluído") -> 2 | O19: =COUNTIFS(tbl_PlanilhaB[Projeto],Base_Projetos[[#This Row],[Projeto]],tbl_PlanilhaB[Status],"Em andamento") -> 0 | P19: =COUNTIFS(tbl_PlanilhaB[Projeto],Base_Projetos[[#This Row],[Projeto]],tbl_PlanilhaB[Status],"Atrasado") -> 0 | Q19: =COUNTIFS(tbl_PlanilhaB[Projeto],Base_Projetos[[#This Row],[Projeto]],tbl_PlanilhaB[Status],"Não iniciado") -> 0 | R19: =IF(Base_Projetos[[#This Row],[Total de tarefas]]=Base_Projetos[[#This Row],[Tarefas Concluídas]],"Concluído",IF(Base_Projetos[[#This Row],[Tarefas não iniciadas]]=Base_Projetos[[#This Row],[Total de tarefas]],"Não iniciado",IF(Base_Projetos[[#This Row],[Tarefas atrasadas]]>0,"Atrasado","Em andamento"))) -> Concluído | S19: =Base_Projetos[[#This Row],[Tarefas Concluídas]]/Base_Projetos[[#This Row],[Total de tarefas]] -> 1
... A38: =A37+1 -> 34 | B38: Gabarito Carro Dianteiro Linha Leve | C38: Desenvolver conceito e o projeto | D38: 2- Média | E38: Fabricio | F38: 1 | G38: =SUMIF(tbl_PlanilhaB[Projeto],Base_Projetos[[#This Row],[Projeto]],tbl_PlanilhaB[Valor previsto]) -> 0 | H38: =SUMIF(tbl_PlanilhaB[Projeto],Base_Projetos[[#This Row],[Projeto]],tbl_PlanilhaB[Valor gasto]) -> 0 | I38: =_xlfn.MINIFS(TAREFAS!E:E,TAREFAS!B:B,Base_Projetos[[#This Row],[Projeto]]) -> 45440 | J38: =_xlfn.MAXIFS(TAREFAS!G:G,TAREFAS!B:B,Base_Projetos[[#This Row],[Projeto]]) -> 45447 | K38: =IF(Base_Projetos[[#This Row],[Total de tarefas]]=Base_Projetos[[#This Row],[Tarefas não iniciadas]],"Não iniciado",_xlfn.MINIFS(TAREFAS!H:H,TAREFAS!B:B,Base_Projetos[[#This Row],[Projeto]])) -> 45440 | L38: =IF(Base_Projetos[[#This Row],[Total de tarefas]]=Base_Projetos[[#This Row],[Tarefas Concluídas]],_xlfn.MAXIFS(TAREFAS!H:H,TAREFAS!B:B,Base_Projetos[[#This Row],[Projeto]]),IF(Base_Projetos[[#This Row],[Total de tarefas]]=Base_Projetos[[#This Row],[Tarefas não iniciadas]],"Não iniciado","Em andamento")) -> 45440 | M38: =SUM(Base_Projetos[[#This Row],[Tarefas Concluídas]:[Tarefas não iniciadas]]) -> 1 | N38: =COUNTIFS(tbl_PlanilhaB[Projeto],Base_Projetos[[#This Row],[Projeto]],tbl_PlanilhaB[Status],"Concluído") -> 1 | O38: =COUNTIFS(tbl_PlanilhaB[Projeto],Base_Projetos[[#This Row],[Projeto]],tbl_PlanilhaB[Status],"Em andamento") -> 0 | P38: =COUNTIFS(tbl_PlanilhaB[Projeto],Base_Projetos[[#This Row],[Projeto]],tbl_PlanilhaB[Status],"Atrasado") -> 0 | Q38: =COUNTIFS(tbl_PlanilhaB[Projeto],Base_Projetos[[#This Row],[Projeto]],tbl_PlanilhaB[Status],"Não iniciado") -> 0 | R38: =IF(Base_Projetos[[#This Row],[Total de tarefas]]=Base_Projetos[[#This Row],[Tarefas Concluídas]],"Concluído",IF(Base_Projetos[[#This Row],[Tarefas não iniciadas]]=Base_Projetos[[#This Row],[Total de tarefas]],"Não iniciado",IF(Base_Projetos[[#This Row],[Tarefas atrasadas]]>0,"Atrasado","Em andamento"))) -> Concluído | S38: =Base_Projetos[[#This Row],[Tarefas Concluídas]]/Base_Projetos[[#This Row],[Total de tarefas]] -> 1
A39: =A38+1 -> 35 | B39: Simulação de Carga Austrália | D39: 3- Alta | E39: Fabricio | F39: 1 | G39: =SUMIF(tbl_PlanilhaB[Projeto],Base_Projetos[[#This Row],[Projeto]],tbl_PlanilhaB[Valor previsto]) -> 0 | H39: =SUMIF(tbl_PlanilhaB[Projeto],Base_Projetos[[#This Row],[Projeto]],tbl_PlanilhaB[Valor gasto]) -> 0 | I39: =_xlfn.MINIFS(TAREFAS!E:E,TAREFAS!B:B,Base_Projetos[[#This Row],[Projeto]]) -> 45415 | J39: =_xlfn.MAXIFS(TAREFAS!G:G,TAREFAS!B:B,Base_Projetos[[#This Row],[Projeto]]) -> 45440 | K39: =IF(Base_Projetos[[#This Row],[Total de tarefas]]=Base_Projetos[[#This Row],[Tarefas não iniciadas]],"Não iniciado",_xlfn.MINIFS(TAREFAS!H:H,TAREFAS!B:B,Base_Projetos[[#This Row],[Projeto]])) -> 45415 | L39: =IF(Base_Projetos[[#This Row],[Total de tarefas]]=Base_Projetos[[#This Row],[Tarefas Concluídas]],_xlfn.MAXIFS(TAREFAS!H:H,TAREFAS!B:B,Base_Projetos[[#This Row],[Projeto]]),IF(Base_Projetos[[#This Row],[Total de tarefas]]=Base_Projetos[[#This Row],[Tarefas não iniciadas]],"Não iniciado","Em andamento")) -> 45433 | M39: =SUM(Base_Projetos[[#This Row],[Tarefas Concluídas]:[Tarefas não iniciadas]]) -> 2 | N39: =COUNTIFS(tbl_PlanilhaB[Projeto],Base_Projetos[[#This Row],[Projeto]],tbl_PlanilhaB[Status],"Concluído") -> 2 | O39: =COUNTIFS(tbl_PlanilhaB[Projeto],Base_Projetos[[#This Row],[Projeto]],tbl_PlanilhaB[Status],"Em andamento") -> 0 | P39: =COUNTIFS(tbl_PlanilhaB[Projeto],Base_Projetos[[#This Row],[Projeto]],tbl_PlanilhaB[Status],"Atrasado") -> 0 | Q39: =COUNTIFS(tbl_PlanilhaB[Projeto],Base_Projetos[[#This Row],[Projeto]],tbl_PlanilhaB[Status],"Não iniciado") -> 0 | R39: =IF(Base_Projetos[[#This Row],[Total de tarefas]]=Base_Projetos[[#This Row],[Tarefas Concluídas]],"Concluído",IF(Base_Projetos[[#This Row],[Tarefas não iniciadas]]=Base_Projetos[[#This Row],[Total de tarefas]],"Não iniciado",IF(Base_Projetos[[#This Row],[Tarefas atrasadas]]>0,"Atrasado","Em andamento"))) -> Concluído | S39: =Base_Projetos[[#This Row],[Tarefas Concluídas]]/Base_Projetos[[#This Row],[Total de tarefas]] -> 1
A40: =A39+1 -> 36 | B40: Suportes para Carga conteiner 2 | C40: projetar suportes para carga | D40: 3- Alta | E40: Evandro | F40: 1 | G40: =SUMIF(tbl_PlanilhaB[Projeto],Base_Projetos[[#This Row],[Projeto]],tbl_PlanilhaB[Valor previsto]) -> 0 | H40: =SUMIF(tbl_PlanilhaB[Projeto],Base_Projetos[[#This Row],[Projeto]],tbl_PlanilhaB[Valor gasto]) -> 0 | I40: =_xlfn.MINIFS(TAREFAS!E:E,TAREFAS!B:B,Base_Projetos[[#This Row],[Projeto]]) -> 45415 | J40: =_xlfn.MAXIFS(TAREFAS!G:G,TAREFAS!B:B,Base_Projetos[[#This Row],[Projeto]]) -> 45439 | K40: =IF(Base_Projetos[[#This Row],[Total de tarefas]]=Base_Projetos[[#This Row],[Tarefas não iniciadas]],"Não iniciado",_xlfn.MINIFS(TAREFAS!H:H,TAREFAS!B:B,Base_Projetos[[#This Row],[Projeto]])) -> 45415 | L40: =IF(Base_Projetos[[#This Row],[Total de tarefas]]=Base_Projetos[[#This Row],[Tarefas Concluídas]],_xlfn.MAXIFS(TAREFAS!H:H,TAREFAS!B:B,Base_Projetos[[#This Row],[Projeto]]),IF(Base_Projetos[[#This Row],[Total de tarefas]]=Base_Projetos[[#This Row],[Tarefas não iniciadas]],"Não iniciado","Em andamento")) -> 45432 | M40: =SUM(Base_Projetos[[#This Row],[Tarefas Concluídas]:[Tarefas não iniciadas]]) -> 3 | N40: =COUNTIFS(tbl_PlanilhaB[Projeto],Base_Projetos[[#This Row],[Projeto]],tbl_PlanilhaB[Status],"Concluído") -> 3 | O40: =COUNTIFS(tbl_PlanilhaB[Projeto],Base_Projetos[[#This Row],[Projeto]],tbl_PlanilhaB[Status],"Em andamento") -> 0 | P40: =COUNTIFS(tbl_PlanilhaB[Projeto],Base_Projetos[[#This Row],[Projeto]],tbl_PlanilhaB[Status],"Atrasado") -> 0 | Q40: =COUNTIFS(tbl_PlanilhaB[Projeto],Base_Projetos[[#This Row],[Projeto]],tbl_PlanilhaB[Status],"Não iniciado") -> 0 | R40: =IF(Base_Projetos[[#This Row],[Total de tarefas]]=Base_Projetos[[#This Row],[Tarefas Concluídas]],"Concluído",IF(Base_Projetos[[#This Row],[Tarefas não iniciadas]]=Base_Projetos[[#This Row],[Total de tarefas]],"Não iniciado",IF(Base_Projetos[[#This Row],[Tarefas atrasadas]]>0,"Atrasado","Em andamento"))) -> Concluído | S40: =Base_Projetos[[#This Row],[Tarefas Concluídas]]/Base_Projetos[[#This Row],[Total de tarefas]] -> 1
A41: =A40+1 -> 37 | B41: Suportes para Carga conteiner 2X32.000 | C41: projetar suportes para carga | D41: 3- Alta | E41: Evandro | F41: 1 | G41: =SUMIF(tbl_PlanilhaB[Projeto],Base_Projetos[[#This Row],[Projeto]],tbl_PlanilhaB[Valor previsto]) -> 0 | H41: =SUMIF(tbl_PlanilhaB[Projeto],Base_Projetos[[#This Row],[Projeto]],tbl_PlanilhaB[Valor gasto]) -> 0 | I41: =_xlfn.MINIFS(TAREFAS!E:E,TAREFAS!B:B,Base_Projetos[[#This Row],[Projeto]]) -> 45423 | J41: =_xlfn.MAXIFS(TAREFAS!G:G,TAREFAS!B:B,Base_Projetos[[#This Row],[Projeto]]) -> 45436 | K41: =IF(Base_Projetos[[#This Row],[Total de tarefas]]=Base_Projetos[[#This Row],[Tarefas não iniciadas]],"Não iniciado",_xlfn.MINIFS(TAREFAS!H:H,TAREFAS!B:B,Base_Projetos[[#This Row],[Projeto]])) -> 45423 | L41: =IF(Base_Projetos[[#This Row],[Total de tarefas]]=Base_Projetos[[#This Row],[Tarefas Concluídas]],_xlfn.MAXIFS(TAREFAS!H:H,TAREFAS!B:B,Base_Projetos[[#This Row],[Projeto]]),IF(Base_Projetos[[#This Row],[Total de tarefas]]=Base_Projetos[[#This Row],[Tarefas não iniciadas]],"Não iniciado","Em andamento")) -> Em andamento | M41: =SUM(Base_Projetos[[#This Row],[Tarefas Concluídas]:[Tarefas não iniciadas]]) -> 3 | N41: =COUNTIFS(tbl_PlanilhaB[Projeto],Base_Projetos[[#This Row],[Projeto]],tbl_PlanilhaB[Status],"Concluído") -> 2 | O41: =COUNTIFS(tbl_PlanilhaB[Projeto],Base_Projetos[[#This Row],[Projeto]],tbl_PlanilhaB[Status],"Em andamento") -> 0 | P41: =COUNTIFS(tbl_PlanilhaB[Projeto],Base_Projetos[[#This Row],[Projeto]],tbl_PlanilhaB[Status],"Atrasado") -> 0 | Q41: =COUNTIFS(tbl_PlanilhaB[Projeto],Base_Projetos[[#This Row],[Projeto]],tbl_PlanilhaB[Status],"Não iniciado") -> 1 | R41: =IF(Base_Projetos[[#This Row],[Total de tarefas]]=Base_Projetos[[#This Row],[Tarefas Concluídas]],"Concluído",IF(Base_Projetos[[#This Row],[Tarefas não iniciadas]]=Base_Projetos[[#This Row],[Total de tarefas]],"Não iniciado",IF(Base_Projetos[[#This Row],[Tarefas atrasadas]]>0,"Atrasado","Em andamento"))) -> Em andamento | S41: =Base_Projetos[[#This Row],[Tarefas Concluídas]]/Base_Projetos[[#This Row],[Total de tarefas]] -> 0.66666667
A42: =A41+1 -> 38 | B42: GAB FRESAGEM SUPORTE LAMINA CRS | C42: PROJETAR E DESENVOLVER GABARITO | D42: 3- Alta | E42: Evandro | F42: 1 | G42: =SUMIF(tbl_PlanilhaB[Projeto],Base_Projetos[[#This Row],[Projeto]],tbl_PlanilhaB[Valor previsto]) -> 0 | H42: =SUMIF(tbl_PlanilhaB[Projeto],Base_Projetos[[#This Row],[Projeto]],tbl_PlanilhaB[Valor gasto]) -> 0 | I42: =_xlfn.MINIFS(TAREFAS!E:E,TAREFAS!B:B,Base_Projetos[[#This Row],[Projeto]]) -> 45436 | J42: =_xlfn.MAXIFS(TAREFAS!G:G,TAREFAS!B:B,Base_Projetos[[#This Row],[Projeto]]) -> 45449 | K42: =IF(Base_Projetos[[#This Row],[Total de tarefas]]=Base_Projetos[[#This Row],[Tarefas não iniciadas]],"Não iniciado",_xlfn.MINIFS(TAREFAS!H:H,TAREFAS!B:B,Base_Projetos[[#This Row],[Projeto]])) -> 45436 | L42: =IF(Base_Projetos[[#This Row],[Total de tarefas]]=Base_Projetos[[#This Row],[Tarefas Concluídas]],_xlfn.MAXIFS(TAREFAS!H:H,TAREFAS!B:B,Base_Projetos[[#This Row],[Projeto]]),IF(Base_Projetos[[#This Row],[Total de tarefas]]=Base_Projetos[[#This Row],[Tarefas não iniciadas]],"Não iniciado","Em andamento")) -> 45444 | M42: =SUM(Base_Projetos[[#This Row],[Tarefas Concluídas]:[Tarefas não iniciadas]]) -> 3 | N42: =COUNTIFS(tbl_PlanilhaB[Projeto],Base_Projetos[[#This Row],[Projeto]],tbl_PlanilhaB[Status],"Concluído") -> 3 | O42: =COUNTIFS(tbl_PlanilhaB[Projeto],Base_Projetos[[#This Row],[Projeto]],tbl_PlanilhaB[Status],"Em andamento") -> 0 | P42: =COUNTIFS(tbl_PlanilhaB[Projeto],Base_Projetos[[#This Row],[Projeto]],tbl_PlanilhaB[Status],"Atrasado") -> 0 | Q42: =COUNTIFS(tbl_PlanilhaB[Projeto],Base_Projetos[[#This Row],[Projeto]],tbl_PlanilhaB[Status],"Não iniciado") -> 0 | R42: =IF(Base_Projetos[[#This Row],[Total de tarefas]]=Base_Projetos[[#This Row],[Tarefas Concluídas]],"Concluído",IF(Base_Projetos[[#This Row],[Tarefas não iniciadas]]=Base_Projetos[[#This Row],[Total de tarefas]],"Não iniciado",IF(Base_Projetos[[#This Row],[Tarefas atrasadas]]>0,"Atrasado","Em andamento"))) -> Concluído | S42: =Base_Projetos[[#This Row],[Tarefas Concluídas]]/Base_Projetos[[#This Row],[Total de tarefas]] -> 1
A43: =A42+1 -> 39 | B43: GAB CHASSI NOVA CRS 7 | C43: PROJETAR E DESENVOLVER GABARITO | D43: 3- Alta | E43: Evandro | F43: 1 | G43: =SUMIF(tbl_PlanilhaB[Projeto],Base_Projetos[[#This Row],[Projeto]],tbl_PlanilhaB[Valor previsto]) -> 0 | H43: =SUMIF(tbl_PlanilhaB[Projeto],Base_Projetos[[#This Row],[Projeto]],tbl_PlanilhaB[Valor gasto]) -> 0 | I43: =_xlfn.MINIFS(TAREFAS!E:E,TAREFAS!B:B,Base_Projetos[[#This Row],[Projeto]]) -> 45441 | J43: =_xlfn.MAXIFS(TAREFAS!G:G,TAREFAS!B:B,Base_Projetos[[#This Row],[Projeto]]) -> 45455 | K43: =IF(Base_Projetos[[#This Row],[Total de tarefas]]=Base_Projetos[[#This Row],[Tarefas não iniciadas]],"Não iniciado",_xlfn.MINIFS(TAREFAS!H:H,TAREFAS!B:B,Base_Projetos[[#This Row],[Projeto]])) -> 45441 | L43: =IF(Base_Projetos[[#This Row],[Total de tarefas]]=Base_Projetos[[#This Row],[Tarefas Concluídas]],_xlfn.MAXIFS(TAREFAS!H:H,TAREFAS!B:B,Base_Projetos[[#This Row],[Projeto]]),IF(Base_Projetos[[#This Row],[Total de tarefas]]=Base_Projetos[[#This Row],[Tarefas não iniciadas]],"Não iniciado","Em andamento")) -> Em andamento | M43: =SUM(Base_Projetos[[#This Row],[Tarefas Concluídas]:[Tarefas não iniciadas]]) -> 4 | N43: =COUNTIFS(tbl_PlanilhaB[Projeto],Base_Projetos[[#This Row],[Projeto]],tbl_PlanilhaB[Status],"Concluído") -> 0 | O43: =COUNTIFS(tbl_PlanilhaB[Projeto],Base_Projetos[[#This Row],[Projeto]],tbl_PlanilhaB[Status],"Em andamento") -> 0 | P43: =COUNTIFS(tbl_PlanilhaB[Projeto],Base_Projetos[[#This Row],[Projeto]],tbl_PlanilhaB[Status],"Atrasado") -> 2 | Q43: =COUNTIFS(tbl_PlanilhaB[Projeto],Base_Projetos[[#This Row],[Projeto]],tbl_PlanilhaB[Status],"Não iniciado") -> 2 | R43: =IF(Base_Projetos[[#This Row],[Total de tarefas]]=Base_Projetos[[#This Row],[Tarefas Concluídas]],"Concluído",IF(Base_Projetos[[#This Row],[Tarefas não iniciadas]]=Base_Projetos[[#This Row],[Total de tarefas]],"Não iniciado",IF(Base_Projetos[[#This Row],[Tarefas atrasadas]]>0,"Atrasado","Em andamento"))) -> Atrasado | S43: =Base_Projetos[[#This Row],[Tarefas Concluídas]]/Base_Projetos[[#This Row],[Total de tarefas]] -> 0
A44: =A43+1 -> 40 | B44: GAB CAÇAMBA CRS 7 NOVA | C44: PROJETAR E DESENVOLVER GABARITO | D44: 3- Alta | E44: Evandro | F44: 1 | G44: =SUMIF(tbl_PlanilhaB[Projeto],Base_Projetos[[#This Row],[Projeto]],tbl_PlanilhaB[Valor previsto]) -> 0 | H44: =SUMIF(tbl_PlanilhaB[Projeto],Base_Projetos[[#This Row],[Projeto]],tbl_PlanilhaB[Valor gasto]) -> 0 | I44: =_xlfn.MINIFS(TAREFAS!E:E,TAREFAS!B:B,Base_Projetos[[#This Row],[Projeto]]) -> 45456 | J44: =_xlfn.MAXIFS(TAREFAS!G:G,TAREFAS!B:B,Base_Projetos[[#This Row],[Projeto]]) -> 45474 | K44: =IF(Base_Projetos[[#This Row],[Total de tarefas]]=Base_Projetos[[#This Row],[Tarefas não iniciadas]],"Não iniciado",_xlfn.MINIFS(TAREFAS!H:H,TAREFAS!B:B,Base_Projetos[[#This Row],[Projeto]])) -> 45456 | L44: =IF(Base_Projetos[[#This Row],[Total de tarefas]]=Base_Projetos[[#This Row],[Tarefas Concluídas]],_xlfn.MAXIFS(TAREFAS!H:H,TAREFAS!B:B,Base_Projetos[[#This Row],[Projeto]]),IF(Base_Projetos[[#This Row],[Total de tarefas]]=Base_Projetos[[#This Row],[Tarefas não iniciadas]],"Não iniciado","Em andamento")) -> 45471 | M44: =SUM(Base_Projetos[[#This Row],[Tarefas Concluídas]:[Tarefas não iniciadas]]) -> 4 | N44: =COUNTIFS(tbl_PlanilhaB[Projeto],Base_Projetos[[#This Row],[Projeto]],tbl_PlanilhaB[Status],"Concluído") -> 4 | O44: =COUNTIFS(tbl_PlanilhaB[Projeto],Base_Projetos[[#This Row],[Projeto]],tbl_PlanilhaB[Status],"Em andamento") -> 0 | P44: =COUNTIFS(tbl_PlanilhaB[Projeto],Base_Projetos[[#This Row],[Projeto]],tbl_PlanilhaB[Status],"Atrasado") -> 0 | Q44: =COUNTIFS(tbl_PlanilhaB[Projeto],Base_Projetos[[#This Row],[Projeto]],tbl_PlanilhaB[Status],"Não iniciado") -> 0 | R44: =IF(Base_Projetos[[#This Row],[Total de tarefas]]=Base_Projetos[[#This Row],[Tarefas Concluídas]],"Concluído",IF(Base_Projetos[[#This Row],[Tarefas não iniciadas]]=Base_Projetos[[#This Row],[Total de tarefas]],"Não iniciado",IF(Base_Projetos[[#This Row],[Tarefas atrasadas]]>0,"Atrasado","Em andamento"))) -> Concluído | S44: =Base_Projetos[[#This Row],[Tarefas Concluídas]]/Base_Projetos[[#This Row],[Total de tarefas]] -> 1
A45: =A44+1 -> 41 | B45: GAB LATERAL CRS3 E 4 PARA ROBO | C45: AJUSTAR GABARITO | D45: 3- Alta | E45: Evandro | F45: 1 | G45: =SUMIF(tbl_PlanilhaB[Projeto],Base_Projetos[[#This Row],[Projeto]],tbl_PlanilhaB[Valor previsto]) -> 0 | H45: =SUMIF(tbl_PlanilhaB[Projeto],Base_Projetos[[#This Row],[Projeto]],tbl_PlanilhaB[Valor gasto]) -> 0 | I45: =_xlfn.MINIFS(TAREFAS!E:E,TAREFAS!B:B,Base_Projetos[[#This Row],[Projeto]]) -> 45444 | J45: =_xlfn.MAXIFS(TAREFAS!G:G,TAREFAS!B:B,Base_Projetos[[#This Row],[Projeto]]) -> 45478 | K45: =IF(Base_Projetos[[#This Row],[Total de tarefas]]=Base_Projetos[[#This Row],[Tarefas não iniciadas]],"Não iniciado",_xlfn.MINIFS(TAREFAS!H:H,TAREFAS!B:B,Base_Projetos[[#This Row],[Projeto]])) -> 45444 | L45: =IF(Base_Projetos[[#This Row],[Total de tarefas]]=Base_Projetos[[#This Row],[Tarefas Concluídas]],_xlfn.MAXIFS(TAREFAS!H:H,TAREFAS!B:B,Base_Projetos[[#This Row],[Projeto]]),IF(Base_Projetos[[#This Row],[Total de tarefas]]=Base_Projetos[[#This Row],[Tarefas não iniciadas]],"Não iniciado","Em andamento")) -> 45476 | M45: =SUM(Base_Projetos[[#This Row],[Tarefas Concluídas]:[Tarefas não iniciadas]]) -> 2 | N45: =COUNTIFS(tbl_PlanilhaB[Projeto],Base_Projetos[[#This Row],[Projeto]],tbl_PlanilhaB[Status],"Concluído") -> 2 | O45: =COUNTIFS(tbl_PlanilhaB[Projeto],Base_Projetos[[#This Row],[Projeto]],tbl_PlanilhaB[Status],"Em andamento") -> 0 | P45: =COUNTIFS(tbl_PlanilhaB[Projeto],Base_Projetos[[#This Row],[Projeto]],tbl_PlanilhaB[Status],"Atrasado") -> 0 | Q45: =COUNTIFS(tbl_PlanilhaB[Projeto],Base_Projetos[[#This Row],[Projeto]],tbl_PlanilhaB[Status],"Não iniciado") -> 0 | R45: =IF(Base_Projetos[[#This Row],[Total de tarefas]]=Base_Projetos[[#This Row],[Tarefas Concluídas]],"Concluído",IF(Base_Projetos[[#This Row],[Tarefas não iniciadas]]=Base_Projetos[[#This Row],[Total de tarefas]],"Não iniciado",IF(Base_Projetos[[#This Row],[Tarefas atrasadas]]>0,"Atrasado","Em andamento"))) -> Concluído | S45: =Base_Projetos[[#This Row],[Tarefas Concluídas]]/Base_Projetos[[#This Row],[Total de tarefas]] -> 1
A46: =A45+1 -> 42 | B46: TANQUE PARA FLUIDO - USINAGEM | C46: MODELAGEM 3D E DETALHAMENTO | D46: 2- Média | E46: Bruno Pivoto | F46: 1 | G46: =SUMIF(tbl_PlanilhaB[Projeto],Base_Projetos[[#This Row],[Projeto]],tbl_PlanilhaB[Valor previsto]) -> 0 | H46: =SUMIF(tbl_PlanilhaB[Projeto],Base_Projetos[[#This Row],[Projeto]],tbl_PlanilhaB[Valor gasto]) -> 0 | I46: =_xlfn.MINIFS(TAREFAS!E:E,TAREFAS!B:B,Base_Projetos[[#This Row],[Projeto]]) -> 45461 | J46: =_xlfn.MAXIFS(TAREFAS!G:G,TAREFAS!B:B,Base_Projetos[[#This Row],[Projeto]]) -> 45464 | K46: =IF(Base_Projetos[[#This Row],[Total de tarefas]]=Base_Projetos[[#This Row],[Tarefas não iniciadas]],"Não iniciado",_xlfn.MINIFS(TAREFAS!H:H,TAREFAS!B:B,Base_Projetos[[#This Row],[Projeto]])) -> 45461 | L46: =IF(Base_Projetos[[#This Row],[Total de tarefas]]=Base_Projetos[[#This Row],[Tarefas Concluídas]],_xlfn.MAXIFS(TAREFAS!H:H,TAREFAS!B:B,Base_Projetos[[#This Row],[Projeto]]),IF(Base_Projetos[[#This Row],[Total de tarefas]]=Base_Projetos[[#This Row],[Tarefas não iniciadas]],"Não iniciado","Em andamento")) -> 45461 | M46: =SUM(Base_Projetos[[#This Row],[Tarefas Concluídas]:[Tarefas não iniciadas]]) -> 1 | N46: =COUNTIFS(tbl_PlanilhaB[Projeto],Base_Projetos[[#This Row],[Projeto]],tbl_PlanilhaB[Status],"Concluído") -> 1 | O46: =COUNTIFS(tbl_PlanilhaB[Projeto],Base_Projetos[[#This Row],[Projeto]],tbl_PlanilhaB[Status],"Em andamento") -> 0 | P46: =COUNTIFS(tbl_PlanilhaB[Projeto],Base_Projetos[[#This Row],[Projeto]],tbl_PlanilhaB[Status],"Atrasado") -> 0 | Q46: =COUNTIFS(tbl_PlanilhaB[Projeto],Base_Projetos[[#This Row],[Projeto]],tbl_PlanilhaB[Status],"Não iniciado") -> 0 | R46: =IF(Base_Projetos[[#This Row],[Total de tarefas]]=Base_Projetos[[#This Row],[Tarefas Concluídas]],"Concluído",IF(Base_Projetos[[#This Row],[Tarefas não iniciadas]]=Base_Projetos[[#This Row],[Total de tarefas]],"Não iniciado",IF(Base_Projetos[[#This Row],[Tarefas atrasadas]]>0,"Atrasado","Em andamento"))) -> Concluído | S46: =Base_Projetos[[#This Row],[Tarefas Concluídas]]/Base_Projetos[[#This Row],[Total de tarefas]] -> 1
A47: =A46+1 -> 43 | B47: GAB. ROTOR BCI 200, 250, 300, 400, 500 | C47: PROJETAR, MODELAR E DETALHAR | D47: 3- Alta | E47: Bruno Pivoto | F47: 1 | G47: =SUMIF(tbl_PlanilhaB[Projeto],Base_Projetos[[#This Row],[Projeto]],tbl_PlanilhaB[Valor previsto]) -> 0 | H47: =SUMIF(tbl_PlanilhaB[Projeto],Base_Projetos[[#This Row],[Projeto]],tbl_PlanilhaB[Valor gasto]) -> 0 | I47: 45469 | J47: 45475 | K47: =IF(Base_Projetos[[#This Row],[Total de tarefas]]=Base_Projetos[[#This Row],[Tarefas não iniciadas]],"Não iniciado",_xlfn.MINIFS(TAREFAS!H:H,TAREFAS!B:B,Base_Projetos[[#This Row],[Projeto]])) -> 45469 | L47: =IF(Base_Projetos[[#This Row],[Total de tarefas]]=Base_Projetos[[#This Row],[Tarefas Concluídas]],_xlfn.MAXIFS(TAREFAS!H:H,TAREFAS!B:B,Base_Projetos[[#This Row],[Projeto]]),IF(Base_Projetos[[#This Row],[Total de tarefas]]=Base_Projetos[[#This Row],[Tarefas não iniciadas]],"Não iniciado","Em andamento")) -> 45469 | M47: =SUM(Base_Projetos[[#This Row],[Tarefas Concluídas]:[Tarefas não iniciadas]]) -> 1 | N47: =COUNTIFS(tbl_PlanilhaB[Projeto],Base_Projetos[[#This Row],[Projeto]],tbl_PlanilhaB[Status],"Concluído") -> 1 | O47: =COUNTIFS(tbl_PlanilhaB[Projeto],Base_Projetos[[#This Row],[Projeto]],tbl_PlanilhaB[Status],"Em andamento") -> 0 | P47: =COUNTIFS(tbl_PlanilhaB[Projeto],Base_Projetos[[#This Row],[Projeto]],tbl_PlanilhaB[Status],"Atrasado") -> 0 | Q47: =COUNTIFS(tbl_PlanilhaB[Projeto],Base_Projetos[[#This Row],[Projeto]],tbl_PlanilhaB[Status],"Não iniciado") -> 0 | R47: =IF(Base_Projetos[[#This Row],[Total de tarefas]]=Base_Projetos[[#This Row],[Tarefas Concluídas]],"Concluído",IF(Base_Projetos[[#This Row],[Tarefas não iniciadas]]=Base_Projetos[[#This Row],[Total de tarefas]],"Não iniciado",IF(Base_Projetos[[#This Row],[Tarefas atrasadas]]>0,"Atrasado","Em andamento"))) -> Concluído | S47: 0.55
A48: =A47+1 -> 44 | B48: MOLDE ZOCOTEC | C48: PROJETAR, MODELAR E DETALHAR | D48: 1- Baixa | E48: Bruno Pivoto | F48: 1 | G48: =SUMIF(tbl_PlanilhaB[Projeto],Base_Projetos[[#This Row],[Projeto]],tbl_PlanilhaB[Valor previsto]) -> 0 | H48: =SUMIF(tbl_PlanilhaB[Projeto],Base_Projetos[[#This Row],[Projeto]],tbl_PlanilhaB[Valor gasto]) -> 0 | I48: 45475 | J48: 45475 | K48: 45475 | L48: 45475 | M48: =SUM(Base_Projetos[[#This Row],[Tarefas Concluídas]:[Tarefas não iniciadas]]) -> 1 | N48: =COUNTIFS(tbl_PlanilhaB[Projeto],Base_Projetos[[#This Row],[Projeto]],tbl_PlanilhaB[Status],"Concluído") -> 1 | O48: =COUNTIFS(tbl_PlanilhaB[Projeto],Base_Projetos[[#This Row],[Projeto]],tbl_PlanilhaB[Status],"Em andamento") -> 0 | P48: =COUNTIFS(tbl_PlanilhaB[Projeto],Base_Projetos[[#This Row],[Projeto]],tbl_PlanilhaB[Status],"Atrasado") -> 0 | Q48: =COUNTIFS(tbl_PlanilhaB[Projeto],Base_Projetos[[#This Row],[Projeto]],tbl_PlanilhaB[Status],"Não iniciado") -> 0 | R48: =IF(Base_Projetos[[#This Row],[Total de tarefas]]=Base_Projetos[[#This Row],[Tarefas Concluídas]],"Concluído",IF(Base_Projetos[[#This Row],[Tarefas não iniciadas]]=Base_Projetos[[#This Row],[Total de tarefas]],"Não iniciado",IF(Base_Projetos[[#This Row],[Tarefas atrasadas]]>0,"Atrasado","Em andamento"))) -> Concluído | S48: =Base_Projetos[[#This Row],[Tarefas Concluídas]]/Base_Projetos[[#This Row],[Total de tarefas]] -> 1
A49: =A48+1 -> 45 | B49: DISPOSITIVO DE FIXAÇÃO CRP 4.5 | C49: PROJETAR, MODELAR E DETALHAR | D49: 3- Alta | E49: Bruno Pivoto | F49: 1 | G49: =SUMIF(tbl_PlanilhaB[Projeto],Base_Projetos[[#This Row],[Projeto]],tbl_PlanilhaB[Valor previsto]) -> 0 | H49: =SUMIF(tbl_PlanilhaB[Projeto],Base_Projetos[[#This Row],[Projeto]],tbl_PlanilhaB[Valor gasto]) -> 0 | I49: 45471 | J49: 45478 | K49: 45471 | L49: =IF(Base_Projetos[[#This Row],[Total de tarefas]]=Base_Projetos[[#This Row],[Tarefas Concluídas]],_xlfn.MAXIFS(TAREFAS!H:H,TAREFAS!B:B,Base_Projetos[[#This Row],[Projeto]]),IF(Base_Projetos[[#This Row],[Total de tarefas]]=Base_Projetos[[#This Row],[Tarefas não iniciadas]],"Não iniciado","Em andamento")) -> Em andamento | M49: 2 | N49: =COUNTIFS(tbl_PlanilhaB[Projeto],Base_Projetos[[#This Row],[Projeto]],tbl_PlanilhaB[Status],"Concluído") -> 1 | O49: =COUNTIFS(tbl_PlanilhaB[Projeto],Base_Projetos[[#This Row],[Projeto]],tbl_PlanilhaB[Status],"Em andamento") -> 0 | P49: =COUNTIFS(tbl_PlanilhaB[Projeto],Base_Projetos[[#This Row],[Projeto]],tbl_PlanilhaB[Status],"Atrasado") -> 0 | Q49: =COUNTIFS(tbl_PlanilhaB[Projeto],Base_Projetos[[#This Row],[Projeto]],tbl_PlanilhaB[Status],"Não iniciado") -> 0 | R49: =IF(Base_Projetos[[#This Row],[Total de tarefas]]=Base_Projetos[[#This Row],[Tarefas Concluídas]],"Concluído",IF(Base_Projetos[[#This Row],[Tarefas não iniciadas]]=Base_Projetos[[#This Row],[Total de tarefas]],"Não iniciado",IF(Base_Projetos[[#This Row],[Tarefas atrasadas]]>0,"Atrasado","Em andamento"))) -> Em andamento | S49: =Base_Projetos[[#This Row],[Tarefas Concluídas]]/Base_Projetos[[#This Row],[Total de tarefas]] -> 0.5
A50: =A49+1 -> 46 | B50: Plataforma BCI 500 Expointer | C50: Modelar estrutura para expor as BCI's na Expointer | D50: 2- Média | E50: Bruno Pivoto | F50: 1 | G50: =SUMIF(tbl_PlanilhaB[Projeto],Base_Projetos[[#This Row],[Projeto]],tbl_PlanilhaB[Valor previsto]) -> 0 | H50: =SUMIF(tbl_PlanilhaB[Projeto],Base_Projetos[[#This Row],[Projeto]],tbl_PlanilhaB[Valor gasto]) -> 0 | I50: 45489 | J50: 45491 | K50: 45489 | L50: 45491 | M50: 3 | N50: =COUNTIFS(tbl_PlanilhaB[Projeto],Base_Projetos[[#This Row],[Projeto]],tbl_PlanilhaB[Status],"Concluído") -> 3 | O50: =COUNTIFS(tbl_PlanilhaB[Projeto],Base_Projetos[[#This Row],[Projeto]],tbl_PlanilhaB[Status],"Em andamento") -> 0 | P50: =COUNTIFS(tbl_PlanilhaB[Projeto],Base_Projetos[[#This Row],[Projeto]],tbl_PlanilhaB[Status],"Atrasado") -> 0 | Q50: =COUNTIFS(tbl_PlanilhaB[Projeto],Base_Projetos[[#This Row],[Projeto]],tbl_PlanilhaB[Status],"Não iniciado") -> 0 | R50: =IF(Base_Projetos[[#This Row],[Total de tarefas]]=Base_Projetos[[#This Row],[Tarefas Concluídas]],"Concluído",IF(Base_Projetos[[#This Row],[Tarefas não iniciadas]]=Base_Projetos[[#This Row],[Total de tarefas]],"Não iniciado",IF(Base_Projetos[[#This Row],[Tarefas atrasadas]]>0,"Atrasado","Em andamento"))) -> Concluído | S50: =Base_Projetos[[#This Row],[Tarefas Concluídas]]/Base_Projetos[[#This Row],[Total de tarefas]] -> 1
A51: =A50+1 -> 47 | B51: Passa ou não Passa Plainas Niveladoras linha leve e pesada | C51: Projetar, Modelar e detalhar | D51: 1- Baixa | E51: Bruno Pivoto | F51: 1 | G51: =SUMIF(tbl_PlanilhaB[Projeto],Base_Projetos[[#This Row],[Projeto]],tbl_PlanilhaB[Valor previsto]) -> 0 | H51: =SUMIF(tbl_PlanilhaB[Projeto],Base_Projetos[[#This Row],[Projeto]],tbl_PlanilhaB[Valor gasto]) -> 0 | I51: 45505 | J51: 45505 | K51: =IF(Base_Projetos[[#This Row],[Total de tarefas]]=Base_Projetos[[#This Row],[Tarefas não iniciadas]],"Não iniciado",_xlfn.MINIFS(TAREFAS!H:H,TAREFAS!B:B,Base_Projetos[[#This Row],[Projeto]])) -> 45505 | L51: =IF(Base_Projetos[[#This Row],[Total de tarefas]]=Base_Projetos[[#This Row],[Tarefas Concluídas]],_xlfn.MAXIFS(TAREFAS!H:H,TAREFAS!B:B,Base_Projetos[[#This Row],[Projeto]]),IF(Base_Projetos[[#This Row],[Total de tarefas]]=Base_Projetos[[#This Row],[Tarefas não iniciadas]],"Não iniciado","Em andamento")) -> 45505 | M51: =SUM(Base_Projetos[[#This Row],[Tarefas Concluídas]:[Tarefas não iniciadas]]) -> 1 | N51: =COUNTIFS(tbl_PlanilhaB[Projeto],Base_Projetos[[#This Row],[Projeto]],tbl_PlanilhaB[Status],"Concluído") -> 1 | O51: =COUNTIFS(tbl_PlanilhaB[Projeto],Base_Projetos[[#This Row],[Projeto]],tbl_PlanilhaB[Status],"Em andamento") -> 0 | P51: =COUNTIFS(tbl_PlanilhaB[Projeto],Base_Projetos[[#This Row],[Projeto]],tbl_PlanilhaB[Status],"Atrasado") -> 0 | Q51: =COUNTIFS(tbl_PlanilhaB[Projeto],Base_Projetos[[#This Row],[Projeto]],tbl_PlanilhaB[Status],"Não iniciado") -> 0 | R51: =IF(Base_Projetos[[#This Row],[Total de tarefas]]=Base_Projetos[[#This Row],[Tarefas Concluídas]],"Concluído",IF(Base_Projetos[[#This Row],[Tarefas não iniciadas]]=Base_Projetos[[#This Row],[Total de tarefas]],"Não iniciado",IF(Base_Projetos[[#This Row],[Tarefas atrasadas]]>0,"Atrasado","Em andamento"))) -> Concluído | S51: =Base_Projetos[[#This Row],[Tarefas Concluídas]]/Base_Projetos[[#This Row],[Total de tarefas]] -> 1
A52: =A51+1 -> 48 | B52: Passa ou não passa flanges superiores AGRIVAL 60L | C52: Projetar, Modelar e detalhar | D52: 1- Baixa | E52: Bruno Pivoto | F52: 1 | G52: =SUMIF(tbl_PlanilhaB[Projeto],Base_Projetos[[#This Row],[Projeto]],tbl_PlanilhaB[Valor previsto]) -> 0 | H52: =SUMIF(tbl_PlanilhaB[Projeto],Base_Projetos[[#This Row],[Projeto]],tbl_PlanilhaB[Valor gasto]) -> 0 | I52: 45509 | J52: 45509 | K52: =IF(Base_Projetos[[#This Row],[Total de tarefas]]=Base_Projetos[[#This Row],[Tarefas não iniciadas]],"Não iniciado",_xlfn.MINIFS(TAREFAS!H:H,TAREFAS!B:B,Base_Projetos[[#This Row],[Projeto]])) -> 45509 | L52: =IF(Base_Projetos[[#This Row],[Total de tarefas]]=Base_Projetos[[#This Row],[Tarefas Concluídas]],_xlfn.MAXIFS(TAREFAS!H:H,TAREFAS!B:B,Base_Projetos[[#This Row],[Projeto]]),IF(Base_Projetos[[#This Row],[Total de tarefas]]=Base_Projetos[[#This Row],[Tarefas não iniciadas]],"Não iniciado","Em andamento")) -> 45509 | M52: =SUM(Base_Projetos[[#This Row],[Tarefas Concluídas]:[Tarefas não iniciadas]]) -> 1 | N52: =COUNTIFS(tbl_PlanilhaB[Projeto],Base_Projetos[[#This Row],[Projeto]],tbl_PlanilhaB[Status],"Concluído") -> 1 | O52: =COUNTIFS(tbl_PlanilhaB[Projeto],Base_Projetos[[#This Row],[Projeto]],tbl_PlanilhaB[Status],"Em andamento") -> 0 | P52: =COUNTIFS(tbl_PlanilhaB[Projeto],Base_Projetos[[#This Row],[Projeto]],tbl_PlanilhaB[Status],"Atrasado") -> 0 | Q52: =COUNTIFS(tbl_PlanilhaB[Projeto],Base_Projetos[[#This Row],[Projeto]],tbl_PlanilhaB[Status],"Não iniciado") -> 0 | R52: =IF(Base_Projetos[[#This Row],[Total de tarefas]]=Base_Projetos[[#This Row],[Tarefas Concluídas]],"Concluído",IF(Base_Projetos[[#This Row],[Tarefas não iniciadas]]=Base_Projetos[[#This Row],[Total de tarefas]],"Não iniciado",IF(Base_Projetos[[#This Row],[Tarefas atrasadas]]>0,"Atrasado","Em andamento"))) -> Concluído | S52: =Base_Projetos[[#This Row],[Tarefas Concluídas]]/Base_Projetos[[#This Row],[Total de tarefas]] -> 1
